Traceback (most recent call last):
  File "/home/azamat/.pyenv/versions/3.10.3/envs/BePro/lib/python3.10/site-packages/django/apps/config.py", line 270, in get_model
    return self.models[model_name.lower()]
KeyError: 'user'

During handling of the above exception, another exception occurred:

Traceback (most recent call last):
  File "/home/azamat/.pyenv/versions/3.10.3/envs/BePro/lib/python3.10/site-packages/django/contrib/auth/__init__.py", line 170, in get_user_model
    return django_apps.get_model(settings.AUTH_USER_MODEL, require_ready=False)
  File "/home/azamat/.pyenv/versions/3.10.3/envs/BePro/lib/python3.10/site-packages/django/apps/registry.py", line 213, in get_model
    return app_config.get_model(model_name, require_ready=require_ready)
  File "/home/azamat/.pyenv/versions/3.10.3/envs/BePro/lib/python3.10/site-packages/django/apps/config.py", line 272, in get_model
    raise LookupError(
LookupError: App 'auth_user' doesn't have a 'User' model.

During handling of the above exception, another exception occurred:

Traceback (most recent call last):
  File "/home/azamat/.pyenv/versions/BePro/bin/celery", line 8, in <module>
    sys.exit(main())
  File "/home/azamat/.pyenv/versions/3.10.3/envs/BePro/lib/python3.10/site-packages/celery/__main__.py", line 15, in main
    sys.exit(_main())
  File "/home/azamat/.pyenv/versions/3.10.3/envs/BePro/lib/python3.10/site-packages/celery/bin/celery.py", line 217, in main
    return celery(auto_envvar_prefix="CELERY")
  File "/home/azamat/.pyenv/versions/3.10.3/envs/BePro/lib/python3.10/site-packages/click/core.py", line 1130, in __call__
    return self.main(*args, **kwargs)
  File "/home/azamat/.pyenv/versions/3.10.3/envs/BePro/lib/python3.10/site-packages/click/core.py", line 1055, in main
    rv = self.invoke(ctx)
  File "/home/azamat/.pyenv/versions/3.10.3/envs/BePro/lib/python3.10/site-packages/click/core.py", line 1657, in invoke
    return _process_result(sub_ctx.command.invoke(sub_ctx))
  File "/home/azamat/.pyenv/versions/3.10.3/envs/BePro/lib/python3.10/site-packages/click/core.py", line 1404, in invoke
    return ctx.invoke(self.callback, **ctx.params)
  File "/home/azamat/.pyenv/versions/3.10.3/envs/BePro/lib/python3.10/site-packages/click/core.py", line 760, in invoke
    return __callback(*args, **kwargs)
  File "/home/azamat/.pyenv/versions/3.10.3/envs/BePro/lib/python3.10/site-packages/click/decorators.py", line 26, in new_func
    return f(get_current_context(), *args, **kwargs)
  File "/home/azamat/.pyenv/versions/3.10.3/envs/BePro/lib/python3.10/site-packages/celery/bin/base.py", line 134, in caller
    return f(ctx, *args, **kwargs)
  File "/home/azamat/.pyenv/versions/3.10.3/envs/BePro/lib/python3.10/site-packages/celery/bin/worker.py", line 343, in worker
    worker = app.Worker(
  File "/home/azamat/.pyenv/versions/3.10.3/envs/BePro/lib/python3.10/site-packages/celery/worker/worker.py", line 94, in __init__
    self.app.loader.init_worker()
  File "/home/azamat/.pyenv/versions/3.10.3/envs/BePro/lib/python3.10/site-packages/celery/loaders/base.py", line 111, in init_worker
    self.import_default_modules()
  File "/home/azamat/.pyenv/versions/3.10.3/envs/BePro/lib/python3.10/site-packages/celery/loaders/base.py", line 105, in import_default_modules
    raise response
  File "/home/azamat/.pyenv/versions/3.10.3/envs/BePro/lib/python3.10/site-packages/celery/utils/dispatch/signal.py", line 276, in send
    response = receiver(signal=self, sender=sender, **named)
  File "/home/azamat/.pyenv/versions/3.10.3/envs/BePro/lib/python3.10/site-packages/celery/fixups/django.py", line 82, in on_import_modules
    self.worker_fixup.validate_models()
  File "/home/azamat/.pyenv/versions/3.10.3/envs/BePro/lib/python3.10/site-packages/celery/fixups/django.py", line 120, in validate_models
    self.django_setup()
  File "/home/azamat/.pyenv/versions/3.10.3/envs/BePro/lib/python3.10/site-packages/celery/fixups/django.py", line 116, in django_setup
    django.setup()
  File "/home/azamat/.pyenv/versions/3.10.3/envs/BePro/lib/python3.10/site-packages/django/__init__.py", line 24, in setup
    apps.populate(settings.INSTALLED_APPS)
  File "/home/azamat/.pyenv/versions/3.10.3/envs/BePro/lib/python3.10/site-packages/django/apps/registry.py", line 116, in populate
    app_config.import_models()
  File "/home/azamat/.pyenv/versions/3.10.3/envs/BePro/lib/python3.10/site-packages/django/apps/config.py", line 304, in import_models
    self.models_module = import_module(models_module_name)
  File "/home/azamat/.pyenv/versions/3.10.3/lib/python3.10/importlib/__init__.py", line 126, in import_module
    return _bootstrap._gcd_import(name[level:], package, level)
  File "<frozen importlib._bootstrap>", line 1050, in _gcd_import
  File "<frozen importlib._bootstrap>", line 1027, in _find_and_load
  File "<frozen importlib._bootstrap>", line 1006, in _find_and_load_unlocked
  File "<frozen importlib._bootstrap>", line 688, in _load_unlocked
  File "<frozen importlib._bootstrap_external>", line 883, in exec_module
  File "<frozen importlib._bootstrap>", line 241, in _call_with_frames_removed
  File "/home/azamat/Developer/Django-Elefanto/BePro/BePro-back/auth_user/models.py", line 13, in <module>
    from auth_user.tasks import send_invitation
  File "/home/azamat/Developer/Django-Elefanto/BePro/BePro-back/auth_user/tasks.py", line 9, in <module>
    User = get_user_model()
  File "/home/azamat/.pyenv/versions/3.10.3/envs/BePro/lib/python3.10/site-packages/django/contrib/auth/__init__.py", line 176, in get_user_model
    raise ImproperlyConfigured(
django.core.exceptions.ImproperlyConfigured: AUTH_USER_MODEL refers to model 'auth_user.User' that has not been installed
 
 -------------- celery@ideapad v5.2.7 (dawn-chorus)
--- ***** ----- 
-- ******* ---- Linux-5.15.0-41-generic-x86_64-with-glibc2.31 2022-07-20 17:04:16
- *** --- * --- 
- ** ---------- [config]
- ** ---------- .> app:         proj:0x7fa0e3005bd0
- ** ---------- .> transport:   redis://127.0.0.1:6379/0
- ** ---------- .> results:     redis://127.0.0.1:6379/0
- *** --- * --- .> concurrency: 12 (prefork)
-- ******* ---- .> task events: OFF (enable -E to monitor tasks in this worker)
--- ***** ----- 
 -------------- [queues]
                .> celery           exchange=celery(direct) key=celery
                

[tasks]
  . auth_user.tasks.send_created_account_notification
  . auth_user.tasks.send_email
  . auth_user.tasks.send_invitation
  . companies.tasks.deactivate_tariff
  . timesheet.tasks.absence_check

[2022-07-20 17:04:16,958: INFO/MainProcess] Connected to redis://127.0.0.1:6379/0
[2022-07-20 17:04:16,960: INFO/MainProcess] mingle: searching for neighbors
[2022-07-20 17:04:17,970: INFO/MainProcess] mingle: all alone
[2022-07-20 17:04:17,980: WARNING/MainProcess] /home/azamat/.pyenv/versions/3.10.3/envs/BePro/lib/python3.10/site-packages/celery/fixups/django.py:203: UserWarning: Using settings.DEBUG leads to a memory
            leak, never use this setting in production environments!
  warnings.warn('''Using settings.DEBUG leads to a memory

[2022-07-20 17:04:17,980: INFO/MainProcess] celery@ideapad ready.

worker: Warm shutdown (MainProcess)
